***** Running 'python3 grade.py a1_autograding_files/b-13.jpg a1_autograding_files/b-13_detected.txt' *****
Unable to init server: Could not connect: Connection refused
Unable to init server: Could not connect: Connection refused

(grade.py:2923145): Gdk-CRITICAL **: 22:14:42.124: gdk_cursor_new_for_display: assertion 'GDK_IS_DISPLAY (display)' failed
