***** Running 'python3 grade.py a1_autograding_files/a-27.jpg a1_autograding_files/a-27_detected.txt' *****
Unable to init server: Could not connect: Connection refused
Unable to init server: Could not connect: Connection refused

(grade.py:2922949): Gdk-CRITICAL **: 22:14:40.284: gdk_cursor_new_for_display: assertion 'GDK_IS_DISPLAY (display)' failed
